Workbook

Sheet Summary
A1: FIRE PLAN — SUMMARY DASHBOARD
A3: KEY MILESTONES
A4: Milestone | B4: Shares | C4: Super | D4: Combined | E4: Notes
A5: Age 45 — Part-Time Starts | B5: ='Share Portfolio'!H12 -> 1350306.2 | C5: =Super!H12 -> 699899.27 | D5: =B5+C5 -> 2050205.5 | E5: Income drops ~50%
A6: Age 50 — Retire | B6: ='Share Portfolio'!H17 -> 2001446 | C6: =Super!H17 -> 1134073.7 | D6: =B6+C6 -> 3135519.8 | E6: ★ Target retirement
A7: Age 55 | B7: ='Share Portfolio'!H22 -> 2569459.8 | C7: =Super!H22 -> 1666326.4 | D7: =B7+C7 -> 4235786.1
A8: Age 60 — Super Unlocks + Payoff | B8: ='Share Portfolio'!H27 -> 2611031.5 | C8: =Super!H27 -> 2448380.2 | D8: =B8+C8 -> 5059411.7 | E8: ★ Debt-free milestone
A9: Age 65 | B9: ='Share Portfolio'!H32 -> 3609876.1 | C9: =Super!H32 -> 3597473.7 | D9: =B9+C9 -> 7207349.8
A11: RETIREMENT METRICS
A12: Annual Drawdown at Retirement (age 51) | B12: ='Share Portfolio'!G18 -> 103266.36
A13: Withdrawal Rate (drawdown ÷ share portfolio at 50) | B13: ='Share Portfolio'!G18/'Share Portfolio'!H17 -> 0.051595877
A14: Mortgage Lump Sum Payoff at Age 60 | B14: =Assumptions!B47 -> 802678
A15: Annual Saving Once Mortgage Paid Off | B15: =Assumptions!$B$15*12 -> 34560
A17: RENOVATION & REDRAW SCHEDULE
A18: Item | B18: Year | C18: Age | D18: Cost | E18: Funded By
A19: Pool Resurfacing | B19: 2 | C19: 37 | D19: =Assumptions!$B$35 -> 10000 | E19: Savings
A20: 4x4 — Payment 1 | B20: 3 | C20: 38 | D20: =Assumptions!$B$36 -> 7500 | E20: Savings
A21: Shed + Golf Simulator | B21: 3 | C21: 38 | D21: =Assumptions!$B$40 -> 80000 | E21: Mortgage Redraw
A22: Master Bedroom + Bathroom | B22: 4 | C22: 39 | D22: =Assumptions!$B$41 -> 60000 | E22: Mortgage Redraw
A23: 4x4 — Payment 2 | B23: 4 | C23: 39 | D23: =Assumptions!$B$37 -> 7500 | E23: Savings
A24: Driveway + Fencing | B24: 15 | C24: 50 | D24: =Assumptions!$B$42 -> 45000 | E24: Mortgage Redraw
A25: Total Mortgage Redraws | D25: =Assumptions!$B$40+Assumptions!$B$41+Assumptions!$B$42 -> 185000 | E25: Impact on lump sum payoff
A27: ASSUMPTIONS SNAPSHOT (change in Assumptions sheet)
A28: Monthly Income (your half) | B28: =Assumptions!$B$10 -> 9167
A29: Annual Bonus (net) | B29: =Assumptions!$B$11 -> 20000
A30: Income Growth Rate | B30: =Assumptions!$B$12 -> 0.03
A31: Mortgage (your half/mo) | B31: =Assumptions!$B$15 -> 2880
A32: Bills (your half/mo, year 1) | B32: =Assumptions!$B$16 -> 2100
A33: Share Return | B33: =Assumptions!$B$32 -> 0.1
A34: Super Return | B34: =Assumptions!$B$27 -> 0.08
A35: Starting Shares | B35: =Assumptions!$B$30 -> 297000
A36: Starting Super | B36: =Assumptions!$B$31 -> 176000

Sheet Assumptions
A1: FIRE PLAN — ASSUMPTIONS (change blue cells to update entire model)
A3: PERSONAL
A4: current_age | B4: 35 | C4: your current age
A5: pt_start_yr | B5: 10 | C5: part-time starts year 10 = age 45
A6: retire_yr | B6: 15 | C6: retire year 15 = age 50
A7: super_access_age | B7: 60 | C7: super preservation age
A9: INCOME (YOUR HALF)
A10: income_mo | B10: 9167 | C10: 4mo x $8,500 + 8mo x $9,500 ÷ 12
A11: bonus_net | B11: 20000 | C11: annual bonus net of tax, ready to invest
A12: income_growth | B12: 0.03 | C12: salary & bonus grow at this rate per year
A14: MONTHLY EXPENSES (YOUR HALF)
A15: mortgage_half | B15: 2880 | C15: half of $5,760 combined repayment
A16: bills_half | B16: 2100 | C16: half of $4,200 combined, grows at bills_growth
A17: bills_growth | B17: 0.03 | C17: bills inflation rate
A18: spending_mo | B18: 800 | C18: personal discretionary spending
A19: dates_mo | B19: 150 | C19: date nights
A20: holidays_mo | B20: 625 | C20: half of $15,000/yr holidays
A21: lifestyle_growth | B21: 0.03 | C21: spending / dates / holidays inflation rate
A22: savings_mo | B22: 750 | C22: monthly amount invested into share portfolio
A23: cash_savings_mo | B23: 750 | C23: monthly cash savings to offset — NOT invested in shares
A24: SUPERANNUATION
A25: super_employer_y1 | B25: 16533 | C25: year 1 employer SG (12% of $137,774 gross — from payslip)
A26: super_employer_y2 | B26: 17222 | C26: year 2+ employer SG (12.5% of $137,774 gross), grows with income
A27: super_return | B27: 0.08 | C27: super fund annual return
A28: super_personal | B28: 10000 | C28: personal concessional contribution from year 6
A29: STARTING BALANCES
A30: shares_start | B30: 297000 | C30: current share portfolio
A31: super_start | B31: 176000 | C31: current super balance
A32: shares_return | B32: 0.1 | C32: share portfolio annual return
A34: ONE-OFF COSTS FROM SAVINGS
A35: pool_cost | B35: 10000 | C35: pool — year 2 (age 37)
A36: fourwd_1 | B36: 7500 | C36: 4x4 first payment — year 3 (age 38)
A37: fourwd_2 | B37: 7500 | C37: 4x4 second payment — year 4 (age 39)
A39: MORTGAGE REDRAWS (added to mortgage balance)
A40: shed_redraw | B40: 80000 | C40: shed + golf simulator — year 3 (age 38)
A41: bedroom_redraw | B41: 60000 | C41: master bedroom + bathroom — year 4 (age 39)
A42: driveway_redraw | B42: 45000 | C42: driveway + fencing — year 15 (age 50)
A44: MORTGAGE DETAILS
A45: mort_repay_combined | B45: 5760 | C45: combined monthly repayment (both halves)
A46: mort_rate | B46: 0.0569 | C46: annual interest rate
...

Sheet Share Portfolio
A1: SHARE PORTFOLIO PROJECTION
A2: Yr | B2: Age | C2: Phase | D2: Opening | E2: Growth | F2: Contrib (FT) | G2: Drawdown (PT) | H2: Drawdown (Ret) | I2: Closing | J2: 4% Rule | K2: Notes
A3: 1 | B3: 36 | C3: Full Time | D3: =Assumptions!B30 -> 297000 | E3: =D3*Assumptions!B32 -> 29700 | F3: =MAX(0,Assumptions!B10*12*(1+Assumptions!B12)^(1-1)+Assumptions!B11*(1+Assumptions!B12)^(1-1)-(Assumptions!B15+Assumptions!B16*(1+Assumptions!B17)^(1-1)+Assumptions!B18*(1+Assumptions!B21)^(1-1)+Assumptions!B19*(1+Assumptions!B21)^(1-1)+Assumptions!B20*(1+Assumptions!B21)^(1-1)+Assumptions!B22+Assumptions!B23)*12-(0+0+0)) -> 33344 | G3: 0 | H3: =D3+E3+F3-G3 -> 360044 | I3: =H3*0.04 -> 14401.76
A4: 2 | B4: 37 | C4: Full Time | D4: =H3 -> 360044 | E4: =D4*Assumptions!B32 -> 36004.4 | F4: =MAX(0,Assumptions!B10*12*(1+Assumptions!B12)^(2-1)+Assumptions!B11*(1+Assumptions!B12)^(2-1)-(Assumptions!B15+Assumptions!B16*(1+Assumptions!B17)^(2-1)+Assumptions!B18*(1+Assumptions!B21)^(2-1)+Assumptions!B19*(1+Assumptions!B21)^(2-1)+Assumptions!B20*(1+Assumptions!B21)^(2-1)+Assumptions!B22+Assumptions!B23)*12-(Assumptions!B35+0+0)) -> 25921.12 | G4: 0 | H4: =D4+E4+F4-G4 -> 421969.52 | I4: =H4*0.04 -> 16878.781
A5: 3 | B5: 38 | C5: Full Time | D5: =H4 -> 421969.52 | E5: =D5*Assumptions!B32 -> 42196.952 | F5: =MAX(0,Assumptions!B10*12*(1+Assumptions!B12)^(3-1)+Assumptions!B11*(1+Assumptions!B12)^(3-1)-(Assumptions!B15+Assumptions!B16*(1+Assumptions!B17)^(3-1)+Assumptions!B18*(1+Assumptions!B21)^(3-1)+Assumptions!B19*(1+Assumptions!B21)^(3-1)+Assumptions!B20*(1+Assumptions!B21)^(3-1)+Assumptions!B22+Assumptions!B23)*12-(0+Assumptions!B36+0)) -> 31075.554 | G5: 0 | H5: =D5+E5+F5-G5 -> 495242.03 | I5: =H5*0.04 -> 19809.681
A6: 4 | B6: 39 | C6: Full Time | D6: =H5 -> 495242.03 | E6: =D6*Assumptions!B32 -> 49524.203 | F6: =MAX(0,Assumptions!B10*12*(1+Assumptions!B12)^(4-1)+Assumptions!B11*(1+Assumptions!B12)^(4-1)-(Assumptions!B15+Assumptions!B16*(1+Assumptions!B17)^(4-1)+Assumptions!B18*(1+Assumptions!B21)^(4-1)+Assumptions!B19*(1+Assumptions!B21)^(4-1)+Assumptions!B20*(1+Assumptions!B21)^(4-1)+Assumptions!B22+Assumptions!B23)*12-(0+0+Assumptions!B37)) -> 33809.62 | G6: 0 | H6: =D6+E6+F6-G6 -> 578575.85 | I6: =H6*0.04 -> 23143.034
A7: 5 | B7: 40 | C7: Full Time | D7: =H6 -> 578575.85 | E7: =D7*Assumptions!B32 -> 57857.585 | F7: =MAX(0,Assumptions!B10*12*(1+Assumptions!B12)^(5-1)+Assumptions!B11*(1+Assumptions!B12)^(5-1)-(Assumptions!B15+Assumptions!B16*(1+Assumptions!B17)^(5-1)+Assumptions!B18*(1+Assumptions!B21)^(5-1)+Assumptions!B19*(1+Assumptions!B21)^(5-1)+Assumptions!B20*(1+Assumptions!B21)^(5-1)+Assumptions!B22+Assumptions!B23)*12-(0+0+0)) -> 44125.709 | G7: 0 | H7: =D7+E7+F7-G7 -> 680559.14 | I7: =H7*0.04 -> 27222.366
A8: 6 | B8: 41 | C8: Full Time | D8: =H7 -> 680559.14 | E8: =D8*Assumptions!B32 -> 68055.914 | F8: =MAX(0,Assumptions!B10*12*(1+Assumptions!B12)^(6-1)+Assumptions!B11*(1+Assumptions!B12)^(6-1)-(Assumptions!B15+Assumptions!B16*(1+Assumptions!B17)^(6-1)+Assumptions!B18*(1+Assumptions!B21)^(6-1)+Assumptions!B19*(1+Assumptions!B21)^(6-1)+Assumptions!B20*(1+Assumptions!B21)^(6-1)+Assumptions!B22+Assumptions!B23)*12-(0+0+0)) -> 47026.28 | G8: 0 | H8: =D8+E8+F8-G8 -> 795641.34 | I8: =H8*0.04 -> 31825.653
A9: 7 | B9: 42 | C9: Full Time | D9: =H8 -> 795641.34 | E9: =D9*Assumptions!B32 -> 79564.134 | F9: =MAX(0,Assumptions!B10*12*(1+Assumptions!B12)^(7-1)+Assumptions!B11*(1+Assumptions!B12)^(7-1)-(Assumptions!B15+Assumptions!B16*(1+Assumptions!B17)^(7-1)+Assumptions!B18*(1+Assumptions!B21)^(7-1)+Assumptions!B19*(1+Assumptions!B21)^(7-1)+Assumptions!B20*(1+Assumptions!B21)^(7-1)+Assumptions!B22+Assumptions!B23)*12-(0+0+0)) -> 50013.868 | G9: 0 | H9: =D9+E9+F9-G9 -> 925219.34 | I9: =H9*0.04 -> 37008.774
A10: 8 | B10: 43 | C10: Full Time | D10: =H9 -> 925219.34 | E10: =D10*Assumptions!B32 -> 92521.934 | F10: =MAX(0,Assumptions!B10*12*(1+Assumptions!B12)^(8-1)+Assumptions!B11*(1+Assumptions!B12)^(8-1)-(Assumptions!B15+Assumptions!B16*(1+Assumptions!B17)^(8-1)+Assumptions!B18*(1+Assumptions!B21)^(8-1)+Assumptions!B19*(1+Assumptions!B21)^(8-1)+Assumptions!B20*(1+Assumptions!B21)^(8-1)+Assumptions!B22+Assumptions!B23)*12-(0+0+0)) -> 53091.085 | G10: 0 | H10: =D10+E10+F10-G10 -> 1070832.4 | I10: =H10*0.04 -> 42833.294
A11: 9 | B11: 44 | C11: Full Time | D11: =H10 -> 1070832.4 | E11: =D11*Assumptions!B32 -> 107083.24 | F11: =MAX(0,Assumptions!B10*12*(1+Assumptions!B12)^(9-1)+Assumptions!B11*(1+Assumptions!B12)^(9-1)-(Assumptions!B15+Assumptions!B16*(1+Assumptions!B17)^(9-1)+Assumptions!B18*(1+Assumptions!B21)^(9-1)+Assumptions!B19*(1+Assumptions!B21)^(9-1)+Assumptions!B20*(1+Assumptions!B21)^(9-1)+Assumptions!B22+Assumptions!B23)*12-(0+0+0)) -> 56260.617 | G11: 0 | H11: =D11+E11+F11-G11 -> 1234176.2 | I11: =H11*0.04 -> 49367.048
A12: 10 | B12: 45 | C12: Part Time | D12: =H11 -> 1234176.2 | E12: =D12*Assumptions!B32 -> 123417.62 | F12: 0 | G12: =MAX(0,(Assumptions!B15+Assumptions!B16*(1+Assumptions!B17)^(10-1)+Assumptions!B18*(1+Assumptions!B21)^(10-1)+Assumptions!B19*(1+Assumptions!B21)^(10-1)+Assumptions!B20*(1+Assumptions!B21)^(10-1))*12-Assumptions!B10*(1+Assumptions!B12)^(10-1)*0.5*12-Assumptions!B11*(1+Assumptions!B12)^(10-1)*0.5) -> 7287.6309 | H12: =D12+E12+F12-G12 -> 1350306.2 | I12: =H12*0.04 -> 54012.248
A13: 11 | B13: 46 | C13: Part Time | D13: =H12 -> 1350306.2 | E13: =D13*Assumptions!B32 -> 135030.62 | F13: 0 | G13: =MAX(0,(Assumptions!B15+Assumptions!B16*(1+Assumptions!B17)^(11-1)+Assumptions!B18*(1+Assumptions!B21)^(11-1)+Assumptions!B19*(1+Assumptions!B21)^(11-1)+Assumptions!B20*(1+Assumptions!B21)^(11-1))*12-Assumptions!B10*(1+Assumptions!B12)^(11-1)*0.5*12-Assumptions!B11*(1+Assumptions!B12)^(11-1)*0.5) -> 6469.4598 | H13: =D13+E13+F13-G13 -> 1478867.4 | I13: =H13*0.04 -> 59154.694
A14: 12 | B14: 47 | C14: Part Time | D14: =H13 -> 1478867.4 | E14: =D14*Assumptions!B32 -> 147886.74 | F14: 0 | G14: =MAX(0,(Assumptions!B15+Assumptions!B16*(1+Assumptions!B17)^(12-1)+Assumptions!B18*(1+Assumptions!B21)^(12-1)+Assumptions!B19*(1+Assumptions!B21)^(12-1)+Assumptions!B20*(1+Assumptions!B21)^(12-1))*12-Assumptions!B10*(1+Assumptions!B12)^(12-1)*0.5*12-Assumptions!B11*(1+Assumptions!B12)^(12-1)*0.5) -> 5626.7436 | H14: =D14+E14+F14-G14 -> 1621127.4 | I14: =H14*0.04 -> 64845.094
A15: 13 | B15: 48 | C15: Part Time | D15: =H14 -> 1621127.4 | E15: =D15*Assumptions!B32 -> 162112.74 | F15: 0 | G15: =MAX(0,(Assumptions!B15+Assumptions!B16*(1+Assumptions!B17)^(13-1)+Assumptions!B18*(1+Assumptions!B21)^(13-1)+Assumptions!B19*(1+Assumptions!B21)^(13-1)+Assumptions!B20*(1+Assumptions!B21)^(13-1))*12-Assumptions!B10*(1+Assumptions!B12)^(13-1)*0.5*12-Assumptions!B11*(1+Assumptions!B12)^(13-1)*0.5) -> 4758.7459 | H15: =D15+E15+F15-G15 -> 1778481.3 | I15: =H15*0.04 -> 71139.254
A16: 14 | B16: 49 | C16: Part Time | D16: =H15 -> 1778481.3 | E16: =D16*Assumptions!B32 -> 177848.13 | F16: 0 | G16: =MAX(0,(Assumptions!B15+Assumptions!B16*(1+Assumptions!B17)^(14-1)+Assumptions!B18*(1+Assumptions!B21)^(14-1)+Assumptions!B19*(1+Assumptions!B21)^(14-1)+Assumptions!B20*(1+Assumptions!B21)^(14-1))*12-Assumptions!B10*(1+Assumptions!B12)^(14-1)*0.5*12-Assumptions!B11*(1+Assumptions!B12)^(14-1)*0.5) -> 3864.7083 | H16: =D16+E16+F16-G16 -> 1952464.8 | I16: =H16*0.04 -> 78098.591
A17: 15 | B17: 50 | C17: Retired | D17: =H16 -> 1952464.8 | E17: =D17*Assumptions!B32 -> 195246.48 | F17: 0 | G17: =MAX(0,(IF(15>=26,0,Assumptions!B15)+Assumptions!B16*(1+Assumptions!B17)^(15-1)+Assumptions!B18*(1+Assumptions!B21)^(15-1)+Assumptions!B19*(1+Assumptions!B21)^(15-1)+Assumptions!B20*(1+Assumptions!B21)^(15-1))*12)+Assumptions!B42+0 -> 146265.21 | H17: =D17+E17+F17-G17 -> 2001446 | I17: =H17*0.04 -> 80057.841
A18: 16 | B18: 51 | C18: Retired | D18: =H17 -> 2001446 | E18: =D18*Assumptions!B32 -> 200144.6 | F18: 0 | G18: =MAX(0,(IF(16>=26,0,Assumptions!B15)+Assumptions!B16*(1+Assumptions!B17)^(16-1)+Assumptions!B18*(1+Assumptions!B21)^(16-1)+Assumptions!B19*(1+Assumptions!B21)^(16-1)+Assumptions!B20*(1+Assumptions!B21)^(16-1))*12)+0+0 -> 103266.36 | H18: =D18+E18+F18-G18 -> 2098324.3 | I18: =H18*0.04 -> 83932.971
A19: 17 | B19: 52 | C19: Retired | D19: =H18 -> 2098324.3 | E19: =D19*Assumptions!B32 -> 209832.43 | F19: 0 | G19: =MAX(0,(IF(17>=26,0,Assumptions!B15)+Assumptions!B16*(1+Assumptions!B17)^(17-1)+Assumptions!B18*(1+Assumptions!B21)^(17-1)+Assumptions!B19*(1+Assumptions!B21)^(17-1)+Assumptions!B20*(1+Assumptions!B21)^(17-1))*12)+0+0 -> 105327.55 | H19: =D19+E19+F19-G19 -> 2202829.2 | I19: =H19*0.04 -> 88113.166
A20: 18 | B20: 53 | C20: Retired | D20: =H19 -> 2202829.2 | E20: =D20*Assumptions!B32 -> 220282.92 | F20: 0 | G20: =MAX(0,(IF(18>=26,0,Assumptions!B15)+Assumptions!B16*(1+Assumptions!B17)^(18-1)+Assumptions!B18*(1+Assumptions!B21)^(18-1)+Assumptions!B19*(1+Assumptions!B21)^(18-1)+Assumptions!B20*(1+Assumptions!B21)^(18-1))*12)+0+0 -> 107450.58 | H20: =D20+E20+F20-G20 -> 2315661.5 | I20: =H20*0.04 -> 92626.459
A21: 19 | B21: 54 | C21: Retired | D21: =H20 -> 2315661.5 | E21: =D21*Assumptions!B32 -> 231566.15 | F21: 0 | G21: =MAX(0,(IF(19>=26,0,Assumptions!B15)+Assumptions!B16*(1+Assumptions!B17)^(19-1)+Assumptions!B18*(1+Assumptions!B21)^(19-1)+Assumptions!B19*(1+Assumptions!B21)^(19-1)+Assumptions!B20*(1+Assumptions!B21)^(19-1))*12)+0+0 -> 109637.3 | H21: =D21+E21+F21-G21 -> 2437590.3 | I21: =H21*0.04 -> 97503.613
A22: 20 | B22: 55 | C22: Retired | D22: =H21 -> 2437590.3 | E22: =D22*Assumptions!B32 -> 243759.03 | F22: 0 | G22: =MAX(0,(IF(20>=26,0,Assumptions!B15)+Assumptions!B16*(1+Assumptions!B17)^(20-1)+Assumptions!B18*(1+Assumptions!B21)^(20-1)+Assumptions!B19*(1+Assumptions!B21)^(20-1)+Assumptions!B20*(1+Assumptions!B21)^(20-1))*12)+0+0 -> 111889.62 | H22: =D22+E22+F22-G22 -> 2569459.8 | I22: =H22*0.04 -> 102778.39
A23: 21 | B23: 56 | C23: Retired | D23: =H22 -> 2569459.8 | E23: =D23*Assumptions!B32 -> 256945.98 | F23: 0 | G23: =MAX(0,(IF(21>=26,0,Assumptions!B15)+Assumptions!B16*(1+Assumptions!B17)^(21-1)+Assumptions!B18*(1+Assumptions!B21)^(21-1)+Assumptions!B19*(1+Assumptions!B21)^(21-1)+Assumptions!B20*(1+Assumptions!B21)^(21-1))*12)+0+0 -> 114209.51 | H23: =D23+E23+F23-G23 -> 2712196.2 | I23: =H23*0.04 -> 108487.85
A24: 22 | B24: 57 | C24: Retired | D24: =H23 -> 2712196.2 | E24: =D24*Assumptions!B32 -> 271219.62 | F24: 0 | G24: =MAX(0,(IF(22>=26,0,Assumptions!B15)+Assumptions!B16*(1+Assumptions!B17)^(22-1)+Assumptions!B18*(1+Assumptions!B21)^(22-1)+Assumptions!B19*(1+Assumptions!B21)^(22-1)+Assumptions!B20*(1+Assumptions!B21)^(22-1))*12)+0+0 -> 116598.99 | H24: =D24+E24+F24-G24 -> 2866816.9 | I24: =H24*0.04 -> 114672.67
A25: 23 | B25: 58 | C25: Retired | D25: =H24 -> 2866816.9 | E25: =D25*Assumptions!B32 -> 286681.69 | F25: 0 | G25: =MAX(0,(IF(23>=26,0,Assumptions!B15)+Assumptions!B16*(1+Assumptions!B17)^(23-1)+Assumptions!B18*(1+Assumptions!B21)^(23-1)+Assumptions!B19*(1+Assumptions!B21)^(23-1)+Assumptions!B20*(1+Assumptions!B21)^(23-1))*12)+0+0 -> 119060.16 | H25: =D25+E25+F25-G25 -> 3034438.4 | I25: =H25*0.04 -> 121377.54
A26: 24 | B26: 59 | C26: Retired | D26: =H25 -> 3034438.4 | E26: =D26*Assumptions!B32 -> 303443.84 | F26: 0 | G26: =MAX(0,(IF(24>=26,0,Assumptions!B15)+Assumptions!B16*(1+Assumptions!B17)^(24-1)+Assumptions!B18*(1+Assumptions!B21)^(24-1)+Assumptions!B19*(1+Assumptions!B21)^(24-1)+Assumptions!B20*(1+Assumptions!B21)^(24-1))*12)+0+0 -> 121595.17 | H26: =D26+E26+F26-G26 -> 3216287.1 | I26: =H26*0.04 -> 128651.48
A27: 25 | B27: 60 | C27: Retired ★ PAYOFF | D27: =H26 -> 3216287.1 | E27: =D27*Assumptions!B32 -> 321628.71 | F27: 0 | G27: =MAX(0,(IF(25>=26,0,Assumptions!B15)+Assumptions!B16*(1+Assumptions!B17)^(25-1)+Assumptions!B18*(1+Assumptions!B21)^(25-1)+Assumptions!B19*(1+Assumptions!B21)^(25-1)+Assumptions!B20*(1+Assumptions!B21)^(25-1))*12)+0+Assumptions!B47 -> 926884.22 | H27: =D27+E27+F27-G27 -> 2611031.5 | I27: =H27*0.04 -> 104441.26
A28: 26 | B28: 61 | C28: Retired | D28: =H27 -> 2611031.5 | E28: =D28*Assumptions!B32 -> 261103.15 | F28: 0 | G28: =MAX(0,(IF(26>=26,0,Assumptions!B15)+Assumptions!B16*(1+Assumptions!B17)^(26-1)+Assumptions!B18*(1+Assumptions!B21)^(26-1)+Assumptions!B19*(1+Assumptions!B21)^(26-1)+Assumptions!B20*(1+Assumptions!B21)^(26-1))*12)+0+0 -> 92335.607 | H28: =D28+E28+F28-G28 -> 2779799.1 | I28: =H28*0.04 -> 111191.96
A29: 27 | B29: 62 | C29: Retired | D29: =H28 -> 2779799.1 | E29: =D29*Assumptions!B32 -> 277979.91 | F29: 0 | G29: =MAX(0,(IF(27>=26,0,Assumptions!B15)+Assumptions!B16*(1+Assumptions!B17)^(27-1)+Assumptions!B18*(1+Assumptions!B21)^(27-1)+Assumptions!B19*(1+Assumptions!B21)^(27-1)+Assumptions!B20*(1+Assumptions!B21)^(27-1))*12)+0+0 -> 95105.675 | H29: =D29+E29+F29-G29 -> 2962673.3 | I29: =H29*0.04 -> 118506.93
A30: 28 | B30: 63 | C30: Retired | D30: =H29 -> 2962673.3 | E30: =D30*Assumptions!B32 -> 296267.33 | F30: 0 | G30: =MAX(0,(IF(28>=26,0,Assumptions!B15)+Assumptions!B16*(1+Assumptions!B17)^(28-1)+Assumptions!B18*(1+Assumptions!B21)^(28-1)+Assumptions!B19*(1+Assumptions!B21)^(28-1)+Assumptions!B20*(1+Assumptions!B21)^(28-1))*12)+0+0 -> 97958.845 | H30: =D30+E30+F30-G30 -> 3160981.8 | I30: =H30*0.04 -> 126439.27
A31: 29 | B31: 64 | C31: Retired | D31: =H30 -> 3160981.8 | E31: =D31*Assumptions!B32 -> 316098.18 | F31: 0 | G31: =MAX(0,(IF(29>=26,0,Assumptions!B15)+Assumptions!B16*(1+Assumptions!B17)^(29-1)+Assumptions!B18*(1+Assumptions!B21)^(29-1)+Assumptions!B19*(1+Assumptions!B21)^(29-1)+Assumptions!B20*(1+Assumptions!B21)^(29-1))*12)+0+0 -> 100897.61 | H31: =D31+E31+F31-G31 -> 3376182.4 | I31: =H31*0.04 -> 135047.3
A32: 30 | B32: 65 | C32: Retired | D32: =H31 -> 3376182.4 | E32: =D32*Assumptions!B32 -> 337618.24 | F32: 0 | G32: =MAX(0,(IF(30>=26,0,Assumptions!B15)+Assumptions!B16*(1+Assumptions!B17)^(30-1)+Assumptions!B18*(1+Assumptions!B21)^(30-1)+Assumptions!B19*(1+Assumptions!B21)^(30-1)+Assumptions!B20*(1+Assumptions!B21)^(30-1))*12)+0+0 -> 103924.54 | H32: =D32+E32+F32-G32 -> 3609876.1 | I32: =H32*0.04 -> 144395.04
A33: 31 | B33: 66 | C33: Retired | D33: =H32 -> 3609876.1 | E33: =D33*Assumptions!B32 -> 360987.61 | F33: 0 | G33: =MAX(0,(IF(31>=26,0,Assumptions!B15)+Assumptions!B16*(1+Assumptions!B17)^(31-1)+Assumptions!B18*(1+Assumptions!B21)^(31-1)+Assumptions!B19*(1+Assumptions!B21)^(31-1)+Assumptions!B20*(1+Assumptions!B21)^(31-1))*12)+0+0 -> 107042.27 | H33: =D33+E33+F33-G33 -> 3863821.4 | I33: =H33*0.04 -> 154552.86

Sheet Super
A1: SUPER PROJECTION
A2: Yr | B2: Age | C2: Phase | D2: Opening | E2: Growth | F2: Employer SG | G2: Personal | H2: Total In | I2: Closing
A3: 1 | B3: 36 | C3: Full Time | D3: =Assumptions!B31 -> 176000 | E3: =D3*Assumptions!B27 -> 14080 | F3: =Assumptions!B25 -> 16533 | G3: =IF(1>=6,Assumptions!B28,0) -> 0 | H3: =D3+E3+F3+G3 -> 206613
A4: 2 | B4: 37 | C4: Full Time | D4: =H3 -> 206613 | E4: =D4*Assumptions!B27 -> 16529.04 | F4: =Assumptions!B26*(1+Assumptions!B12)^(2-2) -> 17222 | G4: =IF(2>=6,Assumptions!B28,0) -> 0 | H4: =D4+E4+F4+G4 -> 240364.04
A5: 3 | B5: 38 | C5: Full Time | D5: =H4 -> 240364.04 | E5: =D5*Assumptions!B27 -> 19229.123 | F5: =Assumptions!B26*(1+Assumptions!B12)^(3-2) -> 17738.66 | G5: =IF(3>=6,Assumptions!B28,0) -> 0 | H5: =D5+E5+F5+G5 -> 277331.82
A6: 4 | B6: 39 | C6: Full Time | D6: =H5 -> 277331.82 | E6: =D6*Assumptions!B27 -> 22186.546 | F6: =Assumptions!B26*(1+Assumptions!B12)^(4-2) -> 18270.82 | G6: =IF(4>=6,Assumptions!B28,0) -> 0 | H6: =D6+E6+F6+G6 -> 317789.19
A7: 5 | B7: 40 | C7: Full Time | D7: =H6 -> 317789.19 | E7: =D7*Assumptions!B27 -> 25423.135 | F7: =Assumptions!B26*(1+Assumptions!B12)^(5-2) -> 18818.944 | G7: =IF(5>=6,Assumptions!B28,0) -> 0 | H7: =D7+E7+F7+G7 -> 362031.27
A8: 6 | B8: 41 | C8: Full Time | D8: =H7 -> 362031.27 | E8: =D8*Assumptions!B27 -> 28962.501 | F8: =Assumptions!B26*(1+Assumptions!B12)^(6-2) -> 19383.513 | G8: =IF(6>=6,Assumptions!B28,0) -> 10000 | H8: =D8+E8+F8+G8 -> 420377.28
A9: 7 | B9: 42 | C9: Full Time | D9: =H8 -> 420377.28 | E9: =D9*Assumptions!B27 -> 33630.183 | F9: =Assumptions!B26*(1+Assumptions!B12)^(7-2) -> 19965.018 | G9: =IF(7>=6,Assumptions!B28,0) -> 10000 | H9: =D9+E9+F9+G9 -> 483972.48
A10: 8 | B10: 43 | C10: Full Time | D10: =H9 -> 483972.48 | E10: =D10*Assumptions!B27 -> 38717.799 | F10: =Assumptions!B26*(1+Assumptions!B12)^(8-2) -> 20563.969 | G10: =IF(8>=6,Assumptions!B28,0) -> 10000 | H10: =D10+E10+F10+G10 -> 553254.25
A11: 9 | B11: 44 | C11: Full Time | D11: =H10 -> 553254.25 | E11: =D11*Assumptions!B27 -> 44260.34 | F11: =Assumptions!B26*(1+Assumptions!B12)^(9-2) -> 21180.888 | G11: =IF(9>=6,Assumptions!B28,0) -> 10000 | H11: =D11+E11+F11+G11 -> 628695.48
A12: 10 | B12: 45 | C12: Part Time | D12: =H11 -> 628695.48 | E12: =D12*Assumptions!B27 -> 50295.638 | F12: =Assumptions!B26*0.5*(1+Assumptions!B12)^(10-2) -> 10908.157 | G12: =Assumptions!B28 -> 10000 | H12: =D12+E12+F12+G12 -> 699899.27
A13: 11 | B13: 46 | C13: Part Time | D13: =H12 -> 699899.27 | E13: =D13*Assumptions!B27 -> 55991.942 | F13: =Assumptions!B26*0.5*(1+Assumptions!B12)^(11-2) -> 11235.402 | G13: =Assumptions!B28 -> 10000 | H13: =D13+E13+F13+G13 -> 777126.62
A14: 12 | B14: 47 | C14: Part Time | D14: =H13 -> 777126.62 | E14: =D14*Assumptions!B27 -> 62170.129 | F14: =Assumptions!B26*0.5*(1+Assumptions!B12)^(12-2) -> 11572.464 | G14: =Assumptions!B28 -> 10000 | H14: =D14+E14+F14+G14 -> 860869.21
A15: 13 | B15: 48 | C15: Part Time | D15: =H14 -> 860869.21 | E15: =D15*Assumptions!B27 -> 68869.537 | F15: =Assumptions!B26*0.5*(1+Assumptions!B12)^(13-2) -> 11919.638 | G15: =Assumptions!B28 -> 10000 | H15: =D15+E15+F15+G15 -> 951658.39
A16: 14 | B16: 49 | C16: Part Time | D16: =H15 -> 951658.39 | E16: =D16*Assumptions!B27 -> 76132.671 | F16: =Assumptions!B26*0.5*(1+Assumptions!B12)^(14-2) -> 12277.227 | G16: =Assumptions!B28 -> 10000 | H16: =D16+E16+F16+G16 -> 1050068.3
A17: 15 | B17: 50 | C17: Retired | D17: =H16 -> 1050068.3 | E17: =D17*Assumptions!B27 -> 84005.463 | F17: 0 | G17: 0 | H17: =D17+E17+F17+G17 -> 1134073.7
A18: 16 | B18: 51 | C18: Retired | D18: =H17 -> 1134073.7 | E18: =D18*Assumptions!B27 -> 90725.9 | F18: 0 | G18: 0 | H18: =D18+E18+F18+G18 -> 1224799.6
A19: 17 | B19: 52 | C19: Retired | D19: =H18 -> 1224799.6 | E19: =D19*Assumptions!B27 -> 97983.972 | F19: 0 | G19: 0 | H19: =D19+E19+F19+G19 -> 1322783.6
A20: 18 | B20: 53 | C20: Retired | D20: =H19 -> 1322783.6 | E20: =D20*Assumptions!B27 -> 105822.69 | F20: 0 | G20: 0 | H20: =D20+E20+F20+G20 -> 1428606.3
A21: 19 | B21: 54 | C21: Retired | D21: =H20 -> 1428606.3 | E21: =D21*Assumptions!B27 -> 114288.5 | F21: 0 | G21: 0 | H21: =D21+E21+F21+G21 -> 1542894.8
A22: 20 | B22: 55 | C22: Retired | D22: =H21 -> 1542894.8 | E22: =D22*Assumptions!B27 -> 123431.58 | F22: 0 | G22: 0 | H22: =D22+E22+F22+G22 -> 1666326.4
A23: 21 | B23: 56 | C23: Retired | D23: =H22 -> 1666326.4 | E23: =D23*Assumptions!B27 -> 133306.11 | F23: 0 | G23: 0 | H23: =D23+E23+F23+G23 -> 1799632.5
A24: 22 | B24: 57 | C24: Retired | D24: =H23 -> 1799632.5 | E24: =D24*Assumptions!B27 -> 143970.6 | F24: 0 | G24: 0 | H24: =D24+E24+F24+G24 -> 1943603.1
A25: 23 | B25: 58 | C25: Retired | D25: =H24 -> 1943603.1 | E25: =D25*Assumptions!B27 -> 155488.25 | F25: 0 | G25: 0 | H25: =D25+E25+F25+G25 -> 2099091.4
A26: 24 | B26: 59 | C26: Retired | D26: =H25 -> 2099091.4 | E26: =D26*Assumptions!B27 -> 167927.31 | F26: 0 | G26: 0 | H26: =D26+E26+F26+G26 -> 2267018.7
A27: 25 | B27: 60 | C27: Retired | D27: =H26 -> 2267018.7 | E27: =D27*Assumptions!B27 -> 181361.49 | F27: 0 | G27: 0 | H27: =D27+E27+F27+G27 -> 2448380.2
A28: 26 | B28: 61 | C28: Retired | D28: =H27 -> 2448380.2 | E28: =D28*Assumptions!B27 -> 195870.41 | F28: 0 | G28: 0 | H28: =D28+E28+F28+G28 -> 2644250.6
A29: 27 | B29: 62 | C29: Retired | D29: =H28 -> 2644250.6 | E29: =D29*Assumptions!B27 -> 211540.05 | F29: 0 | G29: 0 | H29: =D29+E29+F29+G29 -> 2855790.6
A30: 28 | B30: 63 | C30: Retired | D30: =H29 -> 2855790.6 | E30: =D30*Assumptions!B27 -> 228463.25 | F30: 0 | G30: 0 | H30: =D30+E30+F30+G30 -> 3084253.9
A31: 29 | B31: 64 | C31: Retired | D31: =H30 -> 3084253.9 | E31: =D31*Assumptions!B27 -> 246740.31 | F31: 0 | G31: 0 | H31: =D31+E31+F31+G31 -> 3330994.2
A32: 30 | B32: 65 | C32: Retired | D32: =H31 -> 3330994.2 | E32: =D32*Assumptions!B27 -> 266479.53 | F32: 0 | G32: 0 | H32: =D32+E32+F32+G32 -> 3597473.7

Sheet Mortgage
A1: MORTGAGE AMORTISATION TRACKER
A2: Lump Sum Payoff at Age 60 (Year 25): | F2: 814221
A3: Reference cell (used by Share Portfolio sheet): | F3: 814221
A4: NOTE: If you change mortgage assumptions, update the lump sum in F2 and F3 manually (or re-run model)
A6: Yr | B6: Age | C6: Opening | D6: Redraws | E6: Payments | F6: Closing
A7: 1 | B7: 36 | C7: 966901 | E7: 69120 | F7: 952424
A8: 2 | B8: 37 | C8: Shed+Golf redraw $80k | E8: =(D8+80000)*Assumptions!B46 -> 4552 | F8: 937102 | G8: 80000 | H8: =D8+G8-F8 -> -857102
A9: 3 | B9: 38 | C9: Bedroom+Bath redraw $60k | D9: 140000 | E9: =(D9+60000)*Assumptions!B46 -> 11380 | F9: 1069061 | G9: 60000 | H9: =D9+G9-F9 -> -869061
A10: 4 | B10: 39 | C10: 1069061 | E10: 69120 | F10: 1060551
A11: 5 | B11: 40 | C11: 1060551 | E11: 69120 | F11: 1051544
A12: 6 | B12: 41 | C12: 1051544 | E12: 69120 | F12: 1042011
A13: 7 | B13: 42 | C13: 1042011 | E13: 69120 | F13: 1031921
A14: 8 | B14: 43 | C14: 1031921 | E14: 69120 | F14: 1021242
A15: 9 | B15: 44 | C15: 1021242 | E15: 69120 | F15: 1009939
A16: 10 | B16: 45 | C16: 1009939 | E16: 69120 | F16: 997975
A17: 11 | B17: 46 | C17: 997975 | E17: 69120 | F17: 985313
A18: 12 | B18: 47 | C18: 985313 | E18: 69120 | F18: 971912
A19: 13 | B19: 48 | C19: 971912 | E19: 69120 | F19: 957727
A20: 14 | B20: 49 | C20: 957727 | E20: 69120 | F20: 942715
A21: 15 | B21: 50 | C21: 942715 | D21: 45000 | E21: 69120 | F21: 974453
A22: 16 | B22: 51 | C22: 974453 | E22: 69120 | F22: 960417
A23: 17 | B23: 52 | C23: 960417 | E23: 69120 | F23: 945562
A24: 18 | B24: 53 | C24: 945562 | E24: 69120 | F24: 929838
A25: 19 | B25: 54 | C25: 929838 | E25: 69120 | F25: 913196
A26: 20 | B26: 55 | C26: 913196 | E26: 69120 | F26: 895583
A27: 21 | B27: 56 | C27: 895583 | E27: 69120 | F27: 876940
A28: 22 | B28: 57 | C28: 876940 | E28: 69120 | F28: 857209
A29: 23 | B29: 58 | C29: 857209 | E29: 69120 | F29: 836325
A30: 24 | B30: 59 | C30: 836325 | E30: 69120 | F30: 814221
A31: 25 | B31: 60 | C31: 814221 | E31: 69120 | F31: 0
A32: 26 | B32: 61 | C32: 0 | E32: 5760 | F32: 0
A33: 27 | B33: 62 | C33: 0 | E33: 5760 | F33: 0
... A36: 30 | B36: 65 | C36: 0 | E36: 5760 | F36: 0

Sheet Stress Tests
A1: STRESS TEST SCENARIOS
A2: Base: $9,167/mo income | $20k bonus | $2,880 mortgage | $2,000 bills | 10% shares | 8% super | Retire 50
A3: Note: These scenarios use fixed assumptions. Update the base case in the Assumptions sheet to flow through to projections.
A5: Scenario | B5: Retire Age | C5: Shares Return | D5: Bonus (net) | E5: Shares @45 | F5: Shares @Retire | G5: Super @Retire | H5: Annual Drawdown | I5: W/R % | J5: Min Shares | K5: Combined @60 | L5: Result
A6: BASE CASE | B6: 50 | C6: 0.1 | D6: 20000 | E6: 1324706 | F6: 2010414 | G6: 1149376 | H6: 102332 | I6: 0.050900959 | J6: 345244 | K6: 5120852 | L6: ✅ OK
A7: 7% Returns | B7: 50 | C7: 0.07 | D7: 20000 | E7: 1071025 | F7: 1380850 | G7: 930900 | H7: 102332 | I7: 0.074107977 | J7: -36846 | K7: 2035781 | L7: ❌ FAIL
A8: $10k Bonus | B8: 50 | C8: 0.1 | D8: 10000 | E8: 1152683 | F8: 1697617 | G8: 1149376 | H8: 102332 | I8: 0.060279792 | J8: 335244 | K8: 4309537 | L8: ✅ OK
A9: Retire Age 52 | B9: 52 | C9: 0.1 | D9: 20000 | E9: 1324706 | F9: 2446038 | G9: 1394118 | H9: 106459 | I9: 0.043523036 | J9: 345244 | K9: 5713665 | L9: ✅ OK
A10: 7% + $10k Bonus | B10: 50 | C10: 0.07 | D10: 10000 | E10: 921740 | F10: 1138165 | G10: 930900 | H10: 102332 | I10: 0.089909635 | J10: -706421 | K10: 1558384 | L10: ❌ FAIL
A11: 7% + Retire 52 | B11: 52 | C11: 0.07 | D11: 20000 | E11: 1071025 | F11: 1588004 | G11: 1097955 | H11: 106459 | I11: 0.067039504 | J11: 336754 | K11: 2498250 | L11: ✅ OK
A12: Worst Case (all) | B12: 52 | C12: 0.07 | D12: 10000 | E12: 921740 | F12: 1293161 | G12: 1097955 | H12: 106459 | I12: 0.082324629 | J12: -214967 | K12: 1991656 | L12: ❌ FAIL
A15: LEGEND
A16: Green — W/R < 5% (very safe)
A17: Amber — W/R 5–7% (acceptable, portfolio grows)
A18: Red — W/R > 7% or portfolio fails
